import datetime
import time
from pathlib import Path

import pytest
from devtools import debug

from fractal_server.app.db import get_sync_db
from fractal_server.app.models.v1 import ApplyWorkflow
from fractal_server.app.routes.api.v1._aux_functions import (
    _workflow_insert_task,
)
from fractal_server.app.runner.v1 import submit_workflow
from fractal_server.app.schemas.v1 import JobStatusTypeV1


async def test_success_submit_workflows(
    MockCurrentUser,
    db,
    project_factory,
    workflow_factory,
    dataset_factory,
    job_factory,
    resource_factory,
    task_factory,
    tmp_path,
):
    """
    WHEN `submit_worflow` is called twice at different times
    THEN two different folders are created
    """
    async with MockCurrentUser() as user:
        project = await project_factory(user)
        workflow = await workflow_factory(project_id=project.id)
        task = await task_factory(name="task", source="task_source")
        await _workflow_insert_task(
            workflow_id=workflow.id, task_id=task.id, db=db
        )
        dataset = await dataset_factory(project_id=project.id)
        job0 = await job_factory(
            working_dir=tmp_path.as_posix(),
            project_id=project.id,
            input_dataset_id=dataset.id,
            output_dataset_id=dataset.id,
            workflow_id=workflow.id,
        )
        await resource_factory(dataset)

        await submit_workflow(
            workflow_id=workflow.id,
            input_dataset_id=dataset.id,
            output_dataset_id=dataset.id,
            job_id=job0.id,
        )
        with next(get_sync_db()) as _db:
            job1 = _db.get(ApplyWorkflow, job0.id)
        debug(job1.working_dir)
        folder1 = Path(job1.working_dir).name

        time.sleep(1.01)

        await submit_workflow(
            workflow_id=workflow.id,
            input_dataset_id=dataset.id,
            output_dataset_id=dataset.id,
            job_id=job0.id,
        )
        await db.close()
        with next(get_sync_db()) as _db:
            job2 = _db.get(ApplyWorkflow, job0.id)
        debug(job2.working_dir)
        folder2 = Path(job2.working_dir).name

        debug(folder1, folder2)
        assert folder1 != folder2


async def test_fail_submit_workflows_at_same_time(
    MockCurrentUser,
    project_factory,
    workflow_factory,
    dataset_factory,
    job_factory,
    resource_factory,
    task_factory,
    tmp_path,
    monkeypatch,
    db,
):
    """
    WHEN `submit_worflow` is called twice at the "same time" (monkeypatched)
    THEN a RuntimeError is raised
    """
    async with MockCurrentUser() as user:
        project = await project_factory(user)
        workflow = await workflow_factory(project_id=project.id)
        task = await task_factory(name="task", source="task_source")
        await _workflow_insert_task(
            workflow_id=workflow.id, task_id=task.id, db=db
        )
        dataset = await dataset_factory(project_id=project.id)
        job = await job_factory(
            working_dir=tmp_path.as_posix(),
            project_id=project.id,
            input_dataset_id=dataset.id,
            output_dataset_id=dataset.id,
            workflow_id=workflow.id,
        )
        await resource_factory(dataset)

        def patched_get_timestamp():
            return datetime.datetime(
                3000, 1, 1, 0, 0, tzinfo=datetime.timezone.utc
            )

        monkeypatch.setattr(
            "fractal_server.app.runner.v1.get_timestamp", patched_get_timestamp
        )

        await submit_workflow(
            workflow_id=workflow.id,
            input_dataset_id=dataset.id,
            output_dataset_id=dataset.id,
            job_id=job.id,
        )

        await submit_workflow(
            workflow_id=workflow.id,
            input_dataset_id=dataset.id,
            output_dataset_id=dataset.id,
            job_id=job.id,
        )
        await db.refresh(job)
        assert "already exists" in job.log


async def test_fail_submit_workflows_wrong_IDs(
    MockCurrentUser,
    project_factory,
    workflow_factory,
    dataset_factory,
    job_factory,
    resource_factory,
    task_factory,
    tmp_path,
    db,
    override_settings_factory,
):
    async with MockCurrentUser() as user:

        project = await project_factory(user)
        workflow = await workflow_factory(project_id=project.id)
        task = await task_factory(name="task", source="task_source")
        await _workflow_insert_task(
            workflow_id=workflow.id, task_id=task.id, db=db
        )
        dataset = await dataset_factory(project_id=project.id)
        job = await job_factory(
            working_dir=tmp_path.as_posix(),
            project_id=project.id,
            input_dataset_id=dataset.id,
            output_dataset_id=dataset.id,
            workflow_id=workflow.id,
        )
        await resource_factory(dataset)

        # Fail for invalid DB IDs

        with pytest.raises(ValueError):
            await submit_workflow(
                workflow_id=workflow.id,
                input_dataset_id=dataset.id,
                output_dataset_id=dataset.id,
                job_id=9999999,
            )

        await submit_workflow(
            workflow_id=1234,
            input_dataset_id=dataset.id,
            output_dataset_id=dataset.id,
            job_id=job.id,
        )
        await db.refresh(job)
        assert job.status == JobStatusTypeV1.FAILED
        assert job.log == "Cannot fetch workflow 1234 from database\n"

        await submit_workflow(
            workflow_id=workflow.id,
            input_dataset_id=1111,
            output_dataset_id=2222,
            job_id=job.id,
        )
        await db.refresh(job)
        debug(job)
        assert job.status == JobStatusTypeV1.FAILED
        assert job.log == (
            "Cannot fetch input_dataset 1111 from database\n"
            "Cannot fetch output_dataset 2222 from database\n"
        )
